Workbook

Sheet Dados_OS
A1: OS | B1: Data de Abertura | C1: Data de Fechamento | D1: Ano | E1: Mês Fechamento | F1: Equipamento | G1: Tag - Identificação | H1: Tipo_Manutencao | I1: Custo_MO | J1: Custo_Materiais | K1: Tempo_Parada_h | L1: Custo_Total
A2: 51 | B2: 45682.625 | C2: 26/01/2025 00:00 | D2: =YEAR(Tabela1[[#This Row],[Data de Fechamento]]) -> 2025 | E2: =PROPER(TEXT(Tabela1[[#This Row],[Data de Fechamento]],"mmmm")) -> Janeiro | F2: Máquina de Solda | G2: MQS 007 | H2: Corretiva programada | I2: 350 | J2: 0 | K2: =(Tabela1[[#This Row],[Data de Fechamento]]-Tabela1[[#This Row],[Data de Abertura]])*24 -> 9 | L2: =I2+J2 -> 350
A3: 55 | B3: 45705.417 | C3: 20/02/2025 04:00 | D3: =YEAR(Tabela1[[#This Row],[Data de Fechamento]]) -> 2025 | E3: =PROPER(TEXT(Tabela1[[#This Row],[Data de Fechamento]],"mmmm")) -> Fevereiro | F3: Serra Makita | G3: - | H3: Corretiva não programada | I3: 50 | J3: 0 | K3: =(Tabela1[[#This Row],[Data de Fechamento]]-Tabela1[[#This Row],[Data de Abertura]])*24 -> 66 | L3: =I3+J3 -> 50
A4: 58 | B4: 45736.573 | C4: 22/03/2025 03:45 | D4: =YEAR(Tabela1[[#This Row],[Data de Fechamento]]) -> 2025 | E4: =PROPER(TEXT(Tabela1[[#This Row],[Data de Fechamento]],"mmmm")) -> Março | F4: Empilhadeira a Gás Toyota | G4: EMH 001 | H4: Corretiva programada | I4: 500 | J4: 0 | K4: =(Tabela1[[#This Row],[Data de Fechamento]]-Tabela1[[#This Row],[Data de Abertura]])*24 -> 38 | L4: =I4+J4 -> 500
A5: 59 | B5: 45737.5 | C5: 22/03/2025 08:00 | D5: =YEAR(Tabela1[[#This Row],[Data de Fechamento]]) -> 2025 | E5: =PROPER(TEXT(Tabela1[[#This Row],[Data de Fechamento]],"mmmm")) -> Março | F5: Parafusadeira | G5: - | H5: Corretiva não programada | I5: 100 | J5: 0 | K5: =(Tabela1[[#This Row],[Data de Fechamento]]-Tabela1[[#This Row],[Data de Abertura]])*24 -> 20 | L5: =I5+J5 -> 100
A6: 61 | B6: 45731.51 | C6: 45733.052 | D6: =YEAR(Tabela1[[#This Row],[Data de Fechamento]]) -> 2025 | E6: =PROPER(TEXT(Tabela1[[#This Row],[Data de Fechamento]],"mmmm")) -> Março | F6: Centro de Usinagem Vertical ROMI Bridgep Discovery 560 | G6: CCNC 001 | H6: Corretiva não programada | I6: 900 | J6: 433.23 | K6: =(Tabela1[[#This Row],[Data de Fechamento]]-Tabela1[[#This Row],[Data de Abertura]])*24 -> 37 | L6: =I6+J6 -> 1333.23
A7: 64 | B7: 45791.698 | C7: 14/05/2025 23:45 | D7: =YEAR(Tabela1[[#This Row],[Data de Fechamento]]) -> 2025 | E7: =PROPER(TEXT(Tabela1[[#This Row],[Data de Fechamento]],"mmmm")) -> Maio | F7: Compressor Rand Ingersol | G7: COMP 001 | H7: Corretiva não programada | I7: 2250 | J7: 0 | K7: =(Tabela1[[#This Row],[Data de Fechamento]]-Tabela1[[#This Row],[Data de Abertura]])*24 -> 7 | L7: =I7+J7 -> 2250
A8: 100 | B8: 45979.333 | C8: 45980.458 | D8: =YEAR(Tabela1[[#This Row],[Data de Fechamento]]) -> 2025 | E8: =PROPER(TEXT(Tabela1[[#This Row],[Data de Fechamento]],"mmmm")) -> Novembro | F8: Compressor schulz msv 20 | G8: COMP 003 | H8: Corretiva não programada | I8: 500 | J8: 0 | K8: =(Tabela1[[#This Row],[Data de Fechamento]]-Tabela1[[#This Row],[Data de Abertura]])*24 -> 27 | L8: =I8+J8 -> 500
A9: 102 | B9: 45979.396 | C9: 45999.444 | D9: =YEAR(Tabela1[[#This Row],[Data de Fechamento]]) -> 2025 | E9: =PROPER(TEXT(Tabela1[[#This Row],[Data de Fechamento]],"mmmm")) -> Dezembro | F9: Compressor Rand Ingersol | G9: COMP 001 | H9: Corretiva não programada | I9: 1400 | J9: 0 | K9: =(Tabela1[[#This Row],[Data de Fechamento]]-Tabela1[[#This Row],[Data de Abertura]])*24 -> 481.16667 | L9: =I9+J9 -> 1400
A10: 103 | B10: 45993.375 | C10: 45999.583 | D10: =YEAR(Tabela1[[#This Row],[Data de Fechamento]]) -> 2025 | E10: =PROPER(TEXT(Tabela1[[#This Row],[Data de Fechamento]],"mmmm")) -> Dezembro | F10: Torno Convencional | G10: TCNV 003 | H10: Corretiva programada | I10: 0 | J10: 0 | K10: =(Tabela1[[#This Row],[Data de Fechamento]]-Tabela1[[#This Row],[Data de Abertura]])*24 -> 149 | L10: =I10+J10 -> 0
A11: 104 | B11: 45992.417 | C11: 45992.625 | D11: =YEAR(Tabela1[[#This Row],[Data de Fechamento]]) -> 2025 | E11: =PROPER(TEXT(Tabela1[[#This Row],[Data de Fechamento]],"mmmm")) -> Dezembro | F11: Centro de Usinagem Vertical ROMI Bridgep Discovery 560 | G11: CCNC 001 | H11: Corretiva não programada | I11: 400 | J11: 17.62 | K11: =(Tabela1[[#This Row],[Data de Fechamento]]-Tabela1[[#This Row],[Data de Abertura]])*24 -> 5 | L11: =I11+J11 -> 417.62
A12: 106 | B12: 45999.417 | C12: 45999.708 | D12: =YEAR(Tabela1[[#This Row],[Data de Fechamento]]) -> 2025 | E12: =PROPER(TEXT(Tabela1[[#This Row],[Data de Fechamento]],"mmmm")) -> Dezembro | F12: Empilhadeira a Gás Toyota | G12: EMH 001 | H12: Corretiva programada | I12: 1758.2 | J12: 0 | K12: =(Tabela1[[#This Row],[Data de Fechamento]]-Tabela1[[#This Row],[Data de Abertura]])*24 -> 7 | L12: =I12+J12 -> 1758.2
A13: 107 | B13: 46097.542 | C13: 46097.625 | D13: =YEAR(Tabela1[[#This Row],[Data de Fechamento]]) -> 2026 | E13: =PROPER(TEXT(Tabela1[[#This Row],[Data de Fechamento]],"mmmm")) -> Março | F13: Centro de Usinagem Vertical ROMI Bridgep Discovery 560 | G13: CCNC 001 | H13: Corretiva programada | I13: 0 | J13: 460 | K13: =(Tabela1[[#This Row],[Data de Fechamento]]-Tabela1[[#This Row],[Data de Abertura]])*24 -> 2 | L13: =I13+J13 -> 460
A14: 108 | B14: 46038.493 | C14: 46043.442 | D14: =YEAR(Tabela1[[#This Row],[Data de Fechamento]]) -> 2026 | E14: =PROPER(TEXT(Tabela1[[#This Row],[Data de Fechamento]],"mmmm")) -> Janeiro | F14: Compressor Chicago Pneumatic | G14: COMP 002 | H14: Corretiva não programada | I14: 1125 | J14: 0 | K14: =(Tabela1[[#This Row],[Data de Fechamento]]-Tabela1[[#This Row],[Data de Abertura]])*24 -> 118.76667 | L14: =I14+J14 -> 1125
A15: 109 | B15: 46042.493 | C15: 46066.583 | D15: =YEAR(Tabela1[[#This Row],[Data de Fechamento]]) -> 2026 | E15: =PROPER(TEXT(Tabela1[[#This Row],[Data de Fechamento]],"mmmm")) -> Fevereiro | F15: Compressor Rand Ingersol | G15: COMP 001 | H15: Corretiva programada | I15: 850 | J15: 0 | K15: =(Tabela1[[#This Row],[Data de Fechamento]]-Tabela1[[#This Row],[Data de Abertura]])*24 -> 578.16667 | L15: =I15+J15 -> 850
A16: 110 | B16: 46042.375 | C16: 46045.458 | D16: =YEAR(Tabela1[[#This Row],[Data de Fechamento]]) -> 2026 | E16: =PROPER(TEXT(Tabela1[[#This Row],[Data de Fechamento]],"mmmm")) -> Janeiro | F16: Empilhadeira a Gás Toyota | G16: EMH 001 | H16: Corretiva não programada | I16: 945 | J16: 0 | K16: =(Tabela1[[#This Row],[Data de Fechamento]]-Tabela1[[#This Row],[Data de Abertura]])*24 -> 74 | L16: =I16+J16 -> 945
A17: 111 | B17: 46043.375 | C17: 46043.632 | D17: =YEAR(Tabela1[[#This Row],[Data de Fechamento]]) -> 2026 | E17: =PROPER(TEXT(Tabela1[[#This Row],[Data de Fechamento]],"mmmm")) -> Janeiro | F17: Cortadora Plasma | G17: PML 001 | H17: Corretiva programada | I17: 900 | J17: 0 | K17: =(Tabela1[[#This Row],[Data de Fechamento]]-Tabela1[[#This Row],[Data de Abertura]])*24 -> 6.1666667 | L17: =I17+J17 -> 900
A18: 112 | B18: 46049.375 | C18: 46049.458 | D18: =YEAR(Tabela1[[#This Row],[Data de Fechamento]]) -> 2026 | E18: =PROPER(TEXT(Tabela1[[#This Row],[Data de Fechamento]],"mmmm")) -> Janeiro | F18: Serra fita horizontal Franho | G18: SFH 001 | H18: Corretiva não programada | I18: 260 | J18: 0 | K18: =(Tabela1[[#This Row],[Data de Fechamento]]-Tabela1[[#This Row],[Data de Abertura]])*24 -> 2 | L18: =I18+J18 -> 260
A19: 113 | B19: 46056.438 | C19: 46058.667 | D19: =YEAR(Tabela1[[#This Row],[Data de Fechamento]]) -> 2026 | E19: =PROPER(TEXT(Tabela1[[#This Row],[Data de Fechamento]],"mmmm")) -> Fevereiro | F19: Empilhadeira a Gás Toyota | G19: EMH 001 | H19: Corretiva não programada | I19: 800 | J19: 0 | K19: =(Tabela1[[#This Row],[Data de Fechamento]]-Tabela1[[#This Row],[Data de Abertura]])*24 -> 53.5 | L19: =I19+J19 -> 800
... A24: 118 | B24: 46118.396 | C24: 46119.354 | D24: =YEAR(Tabela1[[#This Row],[Data de Fechamento]]) -> 2026 | E24: =PROPER(TEXT(Tabela1[[#This Row],[Data de Fechamento]],"mmmm")) -> Abril | F24: Serra circular Coteza A400 | G24: SRC 001 | H24: Corretiva programada | I24: 0 | J24: 129.33 | K24: =(Tabela1[[#This Row],[Data de Fechamento]]-Tabela1[[#This Row],[Data de Abertura]])*24 -> 23 | L24: =I24+J24 -> 129.33
A25: 119 | B25: 46087.681 | C25: 46098.667 | D25: =YEAR(Tabela1[[#This Row],[Data de Fechamento]]) -> 2026 | E25: =PROPER(TEXT(Tabela1[[#This Row],[Data de Fechamento]],"mmmm")) -> Março | F25: Empilhadeira a Gás Toyota | G25: EMH 001 | H25: Corretiva não programada | I25: =937+1399.99 -> 2336.99 | J25: 6200 | K25: =(Tabela1[[#This Row],[Data de Fechamento]]-Tabela1[[#This Row],[Data de Abertura]])*24 -> 263.66667 | L25: =I25+J25 -> 8536.99
A26: 120 | B26: 46066.542 | C26: 46113.667 | D26: =YEAR(Tabela1[[#This Row],[Data de Fechamento]]) -> 2026 | E26: =PROPER(TEXT(Tabela1[[#This Row],[Data de Fechamento]],"mmmm")) -> Abril | F26: Compressor Schulz MSV 20 MAX 250 | G26: COMP 003 | H26: Corretiva programada | I26: 2000 | J26: 0 | K26: =(Tabela1[[#This Row],[Data de Fechamento]]-Tabela1[[#This Row],[Data de Abertura]])*24 -> 1131 | L26: =I26+J26 -> 2000
A27: 121 | B27: 46108.542 | C27: 46108.625 | D27: =YEAR(Tabela1[[#This Row],[Data de Fechamento]]) -> 2026 | E27: =PROPER(TEXT(Tabela1[[#This Row],[Data de Fechamento]],"mmmm")) -> Março | F27: Torno mecânico Magnum Cut FEL 1440 GWM | G27: TCNV 003 | H27: Corretiva não programada | I27: 0 | J27: 23 | K27: =(Tabela1[[#This Row],[Data de Fechamento]]-Tabela1[[#This Row],[Data de Abertura]])*24 -> 2 | L27: =I27+J27 -> 23
A28: 122 | B28: 46077.542 | C28: 46082.542 | D28: =YEAR(Tabela1[[#This Row],[Data de Fechamento]]) -> 2026 | E28: =PROPER(TEXT(Tabela1[[#This Row],[Data de Fechamento]],"mmmm")) -> Março | F28: Centro de Usinagem Vertical ROMI Bridgep Discovery 560 | G28: CCNC 001 | H28: Corretiva não programada | I28: 0 | J28: 1916.23 | K28: =(Tabela1[[#This Row],[Data de Fechamento]]-Tabela1[[#This Row],[Data de Abertura]])*24 -> 120 | L28: =I28+J28 -> 1916.23
A29: 123 | B29: 46122.333 | C29: 46122.417 | D29: =YEAR(Tabela1[[#This Row],[Data de Fechamento]]) -> 2026 | E29: =PROPER(TEXT(Tabela1[[#This Row],[Data de Fechamento]],"mmmm")) -> Abril | F29: Torno Convencional Romi Tormax 30B | G29: TCNV 001 | H29: Corretiva programada | I29: 0 | J29: 1354 | K29: =(Tabela1[[#This Row],[Data de Fechamento]]-Tabela1[[#This Row],[Data de Abertura]])*24 -> 2 | L29: =I29+J29 -> 1354
A30: - | B30: 45658.333 | C30: 02/01/2025 17:00 | D30: =YEAR(Tabela1[[#This Row],[Data de Fechamento]]) -> 2025 | E30: =PROPER(TEXT(Tabela1[[#This Row],[Data de Fechamento]],"mmmm")) -> Janeiro | F30: - | G30: - | H30: Preventiva | I30: 3850 | J30: 0 | K30: =(Tabela1[[#This Row],[Data de Fechamento]]-Tabela1[[#This Row],[Data de Abertura]])*24 -> 33 | L30: =I30+J30 -> 3850
A31: - | B31: 45689.333 | C31: 02/02/2025 17:00 | D31: =YEAR(Tabela1[[#This Row],[Data de Fechamento]]) -> 2025 | E31: =PROPER(TEXT(Tabela1[[#This Row],[Data de Fechamento]],"mmmm")) -> Fevereiro | F31: - | G31: - | H31: Preventiva | I31: 3167 | J31: 0 | K31: =(Tabela1[[#This Row],[Data de Fechamento]]-Tabela1[[#This Row],[Data de Abertura]])*24 -> 33 | L31: =I31+J31 -> 3167
A32: - | B32: 45697.604 | C32: 11/02/2025 02:30 | D32: =YEAR(Tabela1[[#This Row],[Data de Fechamento]]) -> 2025 | E32: =PROPER(TEXT(Tabela1[[#This Row],[Data de Fechamento]],"mmmm")) -> Fevereiro | F32: Compressor schulz msv 20 | G32: COMP 003 | H32: Corretiva não programada | I32: 983 | J32: 0 | K32: =(Tabela1[[#This Row],[Data de Fechamento]]-Tabela1[[#This Row],[Data de Abertura]])*24 -> 36 | L32: =I32+J32 -> 983
A33: - | B33: 45717.333 | C33: 02/03/2025 17:00 | D33: =YEAR(Tabela1[[#This Row],[Data de Fechamento]]) -> 2025 | E33: =PROPER(TEXT(Tabela1[[#This Row],[Data de Fechamento]],"mmmm")) -> Março | F33: - | G33: - | H33: Preventiva | I33: 2700 | J33: 0 | K33: =(Tabela1[[#This Row],[Data de Fechamento]]-Tabela1[[#This Row],[Data de Abertura]])*24 -> 33 | L33: =I33+J33 -> 2700
A34: - | B34: 45719.51 | C34: 03/03/2025 23:15 | D34: =YEAR(Tabela1[[#This Row],[Data de Fechamento]]) -> 2025 | E34: =PROPER(TEXT(Tabela1[[#This Row],[Data de Fechamento]],"mmmm")) -> Março | F34: Serra Makita | G34: - | H34: Corretiva não programada | I34: 100 | J34: 0 | K34: =(Tabela1[[#This Row],[Data de Fechamento]]-Tabela1[[#This Row],[Data de Abertura]])*24 -> 11 | L34: =I34+J34 -> 100
A35: - | B35: 45748.333 | C35: 02/04/2025 17:00 | D35: =YEAR(Tabela1[[#This Row],[Data de Fechamento]]) -> 2025 | E35: =PROPER(TEXT(Tabela1[[#This Row],[Data de Fechamento]],"mmmm")) -> Abril | F35: - | G35: - | H35: Preventiva | I35: 2775 | J35: 0 | K35: =(Tabela1[[#This Row],[Data de Fechamento]]-Tabela1[[#This Row],[Data de Abertura]])*24 -> 33 | L35: =I35+J35 -> 2775
A36: - | B36: 45759.656 | C36: 13/04/2025 07:45 | D36: =YEAR(Tabela1[[#This Row],[Data de Fechamento]]) -> 2025 | E36: =PROPER(TEXT(Tabela1[[#This Row],[Data de Fechamento]],"mmmm")) -> Abril | F36: Compressor Schulz MSV 20 MAX 250 | G36: COMP 003 | H36: Corretiva programada | I36: 525 | J36: 101.72 | K36: =(Tabela1[[#This Row],[Data de Fechamento]]-Tabela1[[#This Row],[Data de Abertura]])*24 -> 16 | L36: =I36+J36 -> 626.72
A37: - | B37: 45778.333 | C37: 02/05/2025 17:00 | D37: =YEAR(Tabela1[[#This Row],[Data de Fechamento]]) -> 2025 | E37: =PROPER(TEXT(Tabela1[[#This Row],[Data de Fechamento]],"mmmm")) -> Maio | F37: - | G37: - | H37: Preventiva | I37: 3687 | J37: 0 | K37: =(Tabela1[[#This Row],[Data de Fechamento]]-Tabela1[[#This Row],[Data de Abertura]])*24 -> 33 | L37: =I37+J37 -> 3687
A38: - | B38: 45780.635 | C38: 06/05/2025 13:15 | D38: =YEAR(Tabela1[[#This Row],[Data de Fechamento]]) -> 2025 | E38: =PROPER(TEXT(Tabela1[[#This Row],[Data de Fechamento]],"mmmm")) -> Maio | F38: Esmerilhadeira | G38: 1-M9510 | H38: Corretiva não programada | I38: 300 | J38: 270.65 | K38: =(Tabela1[[#This Row],[Data de Fechamento]]-Tabela1[[#This Row],[Data de Abertura]])*24 -> 70 | L38: =I38+J38 -> 570.65
A39: - | B39: 45785.635 | C39: 45785.688 | D39: =YEAR(Tabela1[[#This Row],[Data de Fechamento]]) -> 2025 | E39: =PROPER(TEXT(Tabela1[[#This Row],[Data de Fechamento]],"mmmm")) -> Maio | F39: Torno Convencional | G39: TCNV 003 | H39: Corretiva programada | I39: 400 | J39: 155 | K39: =(Tabela1[[#This Row],[Data de Fechamento]]-Tabela1[[#This Row],[Data de Abertura]])*24 -> 1.25 | L39: =I39+J39 -> 555
A40: - | B40: 45809.333 | C40: 45810.708 | D40: =YEAR(Tabela1[[#This Row],[Data de Fechamento]]) -> 2025 | E40: =PROPER(TEXT(Tabela1[[#This Row],[Data de Fechamento]],"mmmm")) -> Junho | F40: - | G40: - | H40: Preventiva | I40: 4200 | J40: 0 | K40: =(Tabela1[[#This Row],[Data de Fechamento]]-Tabela1[[#This Row],[Data de Abertura]])*24 -> 33 | L40: =I40+J40 -> 4200
A41: - | B41: 45809.333 | C41: 45810.708 | D41: =YEAR(Tabela1[[#This Row],[Data de Fechamento]]) -> 2025 | E41: =PROPER(TEXT(Tabela1[[#This Row],[Data de Fechamento]],"mmmm")) -> Junho | F41: Máquina de Solda | G41: MQS 007 | H41: Corretiva não programada | I41: 503.03 | J41: 0 | K41: =(Tabela1[[#This Row],[Data de Fechamento]]-Tabela1[[#This Row],[Data de Abertura]])*24 -> 33 | L41: =I41+J41 -> 503.03
A42: - | B42: 45839.333 | C42: 45840.708 | D42: =YEAR(Tabela1[[#This Row],[Data de Fechamento]]) -> 2025 | E42: =PROPER(TEXT(Tabela1[[#This Row],[Data de Fechamento]],"mmmm")) -> Julho | F42: - | G42: - | H42: Preventiva | I42: 4200 | J42: 0 | K42: =(Tabela1[[#This Row],[Data de Fechamento]]-Tabela1[[#This Row],[Data de Abertura]])*24 -> 33 | L42: =I42+J42 -> 4200
A43: - | B43: 45870.292 | C43: 45871.708 | D43: =YEAR(Tabela1[[#This Row],[Data de Fechamento]]) -> 2025 | E43: =PROPER(TEXT(Tabela1[[#This Row],[Data de Fechamento]],"mmmm")) -> Agosto | F43: - | G43: - | H43: Preventiva | I43: 2100 | J43: 0 | K43: =(Tabela1[[#This Row],[Data de Fechamento]]-Tabela1[[#This Row],[Data de Abertura]])*24 -> 34 | L43: =I43+J43 -> 2100
A44: - | B44: 45875.417 | C44: 45876.583 | D44: =YEAR(Tabela1[[#This Row],[Data de Fechamento]]) -> 2025 | E44: =PROPER(TEXT(Tabela1[[#This Row],[Data de Fechamento]],"mmmm")) -> Agosto | F44: Empilhadeira a Gás Toyota | G44: EMH 001 | H44: Corretiva programada | I44: 2372.14 | J44: 0 | K44: =(Tabela1[[#This Row],[Data de Fechamento]]-Tabela1[[#This Row],[Data de Abertura]])*24 -> 28 | L44: =I44+J44 -> 2372.14
...

Sheet Tratamento de Dados 2025
B1: Resumo de Custos por Tipo de Manutenção | D1: 2025 | F1: Meta | G1: 0.005
B2: Tipo de manutenção | C2: Custo Total por tipo de manutenção (R$) | D2: Percentual de custo total por tipo
B3: Corretiva não programada | C3: =SUMIFS(Dados_OS!L:L,Dados_OS!H:H,Tabela5[[#This Row],[Tipo de manutenção]],Dados_OS!D:D,'Tratamento de Dados 2025'!$D$1) -> 8507.53 | D3: =Tabela5[[#This Row],[Custo Total por tipo de manutenção (R$)]]/SUM(Tabela5[Custo Total por tipo de manutenção (R$)]) -> 0.17497145
B4: Corretiva programada | C4: =SUMIFS(Dados_OS!L:L,Dados_OS!H:H,Tabela5[[#This Row],[Tipo de manutenção]],Dados_OS!D:D,'Tratamento de Dados 2025'!$D$1) -> 11285.86 | D4: =Tabela5[[#This Row],[Custo Total por tipo de manutenção (R$)]]/SUM(Tabela5[Custo Total por tipo de manutenção (R$)]) -> 0.23211241
B5: Preventiva | C5: =SUMIFS(Dados_OS!L:L,Dados_OS!H:H,Tabela5[[#This Row],[Tipo de manutenção]],Dados_OS!D:D,'Tratamento de Dados 2025'!$D$1) -> 28829 | D5: =Tabela5[[#This Row],[Custo Total por tipo de manutenção (R$)]]/SUM(Tabela5[Custo Total por tipo de manutenção (R$)]) -> 0.59291614
B6: Preditiva | C6: =SUMIFS(Dados_OS!L:L,Dados_OS!H:H,Tabela5[[#This Row],[Tipo de manutenção]],Dados_OS!D:D,'Tratamento de Dados 2025'!$D$1) -> 0 | D6: =Tabela5[[#This Row],[Custo Total por tipo de manutenção (R$)]]/SUM(Tabela5[Custo Total por tipo de manutenção (R$)]) -> 0
B7: Melhoria | C7: =SUMIFS(Dados_OS!L:L,Dados_OS!H:H,Tabela5[[#This Row],[Tipo de manutenção]],Dados_OS!D:D,'Tratamento de Dados 2025'!$D$1) -> 0 | D7: =Tabela5[[#This Row],[Custo Total por tipo de manutenção (R$)]]/SUM(Tabela5[Custo Total por tipo de manutenção (R$)]) -> 0
D8: =SUM(D3:D7) -> 1
A10: Custo de manutenção mensal
A11: Faturemento Mensal | B11: Ano | C11: Mês | D11: Corretiva não programada | E11: Corretiva programada | F11: Preventiva | G11: Preditiva | H11: Melhoria de Máquinas | I11: 0,5% do Faturamento Bruto Mensal | J11: total
A12: 801322.87 | B12: 2025 | C12: Janeiro | D12: =SUMIFS(Tabela1[[Custo_Total]:[Custo_Total]],Tabela1[[Tipo_Manutencao]:[Tipo_Manutencao]],'Tratamento de Dados 2025'!D$11,Tabela1[[Mês Fechamento]:[Mês Fechamento]],'Tratamento de Dados 2025'!$C12,Tabela1[[Ano]:[Ano]],'Tratamento de Dados 2025'!$B12) -> 0 | E12: =SUMIFS(Tabela1[[Custo_Total]:[Custo_Total]],Tabela1[[Tipo_Manutencao]:[Tipo_Manutencao]],'Tratamento de Dados 2025'!E$11,Tabela1[[Mês Fechamento]:[Mês Fechamento]],'Tratamento de Dados 2025'!$C12,Tabela1[[Ano]:[Ano]],'Tratamento de Dados 2025'!$B12) -> 350 | F12: =SUMIFS(Tabela1[[Custo_Total]:[Custo_Total]],Tabela1[[Tipo_Manutencao]:[Tipo_Manutencao]],'Tratamento de Dados 2025'!F$11,Tabela1[[Mês Fechamento]:[Mês Fechamento]],'Tratamento de Dados 2025'!$C12,Tabela1[[Ano]:[Ano]],'Tratamento de Dados 2025'!$B12) -> 3850 | G12: =SUMIFS(Tabela1[[Custo_Total]:[Custo_Total]],Tabela1[[Tipo_Manutencao]:[Tipo_Manutencao]],'Tratamento de Dados 2025'!G$11,Tabela1[[Mês Fechamento]:[Mês Fechamento]],'Tratamento de Dados 2025'!$C12,Tabela1[[Ano]:[Ano]],'Tratamento de Dados 2025'!$B12) -> 0 | H12: =SUMIFS(Tabela1[[Custo_Total]:[Custo_Total]],Tabela1[[Tipo_Manutencao]:[Tipo_Manutencao]],'Tratamento de Dados 2025'!H$11,Tabela1[[Mês Fechamento]:[Mês Fechamento]],'Tratamento de Dados 2025'!$C12,Tabela1[[Ano]:[Ano]],'Tratamento de Dados 2025'!$B12) -> 0 | I12: =Tabela4[[#This Row],[Faturemento Mensal]]*$G$1 -> 4006.6144 | J12: =SUM(Tabela4[[#This Row],[Corretiva não programada]:[Melhoria de Máquinas]]) -> 4200
A13: 1311185.7 | B13: 2025 | C13: Fevereiro | D13: =SUMIFS(Tabela1[[Custo_Total]:[Custo_Total]],Tabela1[[Tipo_Manutencao]:[Tipo_Manutencao]],'Tratamento de Dados 2025'!D$11,Tabela1[[Mês Fechamento]:[Mês Fechamento]],'Tratamento de Dados 2025'!$C13,Tabela1[[Ano]:[Ano]],'Tratamento de Dados 2025'!$B13) -> 1033 | E13: =SUMIFS(Tabela1[[Custo_Total]:[Custo_Total]],Tabela1[[Tipo_Manutencao]:[Tipo_Manutencao]],'Tratamento de Dados 2025'!E$11,Tabela1[[Mês Fechamento]:[Mês Fechamento]],'Tratamento de Dados 2025'!$C13,Tabela1[[Ano]:[Ano]],'Tratamento de Dados 2025'!$B13) -> 0 | F13: =SUMIFS(Tabela1[[Custo_Total]:[Custo_Total]],Tabela1[[Tipo_Manutencao]:[Tipo_Manutencao]],'Tratamento de Dados 2025'!F$11,Tabela1[[Mês Fechamento]:[Mês Fechamento]],'Tratamento de Dados 2025'!$C13,Tabela1[[Ano]:[Ano]],'Tratamento de Dados 2025'!$B13) -> 3167 | G13: =SUMIFS(Tabela1[[Custo_Total]:[Custo_Total]],Tabela1[[Tipo_Manutencao]:[Tipo_Manutencao]],'Tratamento de Dados 2025'!G$11,Tabela1[[Mês Fechamento]:[Mês Fechamento]],'Tratamento de Dados 2025'!$C13,Tabela1[[Ano]:[Ano]],'Tratamento de Dados 2025'!$B13) -> 0 | H13: =SUMIFS(Tabela1[[Custo_Total]:[Custo_Total]],Tabela1[[Tipo_Manutencao]:[Tipo_Manutencao]],'Tratamento de Dados 2025'!H$11,Tabela1[[Mês Fechamento]:[Mês Fechamento]],'Tratamento de Dados 2025'!$C13,Tabela1[[Ano]:[Ano]],'Tratamento de Dados 2025'!$B13) -> 0 | I13: =Tabela4[[#This Row],[Faturemento Mensal]]*$G$1 -> 6555.9286 | J13: =SUM(Tabela4[[#This Row],[Corretiva não programada]:[Melhoria de Máquinas]]) -> 4200
A14: 1030344.2 | B14: 2025 | C14: Março | D14: =SUMIFS(Tabela1[[Custo_Total]:[Custo_Total]],Tabela1[[Tipo_Manutencao]:[Tipo_Manutencao]],'Tratamento de Dados 2025'!D$11,Tabela1[[Mês Fechamento]:[Mês Fechamento]],'Tratamento de Dados 2025'!$C14,Tabela1[[Ano]:[Ano]],'Tratamento de Dados 2025'!$B14) -> 1533.23 | E14: =SUMIFS(Tabela1[[Custo_Total]:[Custo_Total]],Tabela1[[Tipo_Manutencao]:[Tipo_Manutencao]],'Tratamento de Dados 2025'!E$11,Tabela1[[Mês Fechamento]:[Mês Fechamento]],'Tratamento de Dados 2025'!$C14,Tabela1[[Ano]:[Ano]],'Tratamento de Dados 2025'!$B14) -> 500 | F14: =SUMIFS(Tabela1[[Custo_Total]:[Custo_Total]],Tabela1[[Tipo_Manutencao]:[Tipo_Manutencao]],'Tratamento de Dados 2025'!F$11,Tabela1[[Mês Fechamento]:[Mês Fechamento]],'Tratamento de Dados 2025'!$C14,Tabela1[[Ano]:[Ano]],'Tratamento de Dados 2025'!$B14) -> 2700 | G14: =SUMIFS(Tabela1[[Custo_Total]:[Custo_Total]],Tabela1[[Tipo_Manutencao]:[Tipo_Manutencao]],'Tratamento de Dados 2025'!G$11,Tabela1[[Mês Fechamento]:[Mês Fechamento]],'Tratamento de Dados 2025'!$C14,Tabela1[[Ano]:[Ano]],'Tratamento de Dados 2025'!$B14) -> 0 | H14: =SUMIFS(Tabela1[[Custo_Total]:[Custo_Total]],Tabela1[[Tipo_Manutencao]:[Tipo_Manutencao]],'Tratamento de Dados 2025'!H$11,Tabela1[[Mês Fechamento]:[Mês Fechamento]],'Tratamento de Dados 2025'!$C14,Tabela1[[Ano]:[Ano]],'Tratamento de Dados 2025'!$B14) -> 0 | I14: =Tabela4[[#This Row],[Faturemento Mensal]]*$G$1 -> 5151.7211 | J14: =SUM(Tabela4[[#This Row],[Corretiva não programada]:[Melhoria de Máquinas]]) -> 4733.23
A15: 761326.55 | B15: 2025 | C15: Abril | D15: =SUMIFS(Tabela1[[Custo_Total]:[Custo_Total]],Tabela1[[Tipo_Manutencao]:[Tipo_Manutencao]],'Tratamento de Dados 2025'!D$11,Tabela1[[Mês Fechamento]:[Mês Fechamento]],'Tratamento de Dados 2025'!$C15,Tabela1[[Ano]:[Ano]],'Tratamento de Dados 2025'!$B15) -> 0 | E15: =SUMIFS(Tabela1[[Custo_Total]:[Custo_Total]],Tabela1[[Tipo_Manutencao]:[Tipo_Manutencao]],'Tratamento de Dados 2025'!E$11,Tabela1[[Mês Fechamento]:[Mês Fechamento]],'Tratamento de Dados 2025'!$C15,Tabela1[[Ano]:[Ano]],'Tratamento de Dados 2025'!$B15) -> 626.72 | F15: =SUMIFS(Tabela1[[Custo_Total]:[Custo_Total]],Tabela1[[Tipo_Manutencao]:[Tipo_Manutencao]],'Tratamento de Dados 2025'!F$11,Tabela1[[Mês Fechamento]:[Mês Fechamento]],'Tratamento de Dados 2025'!$C15,Tabela1[[Ano]:[Ano]],'Tratamento de Dados 2025'!$B15) -> 2775 | G15: =SUMIFS(Tabela1[[Custo_Total]:[Custo_Total]],Tabela1[[Tipo_Manutencao]:[Tipo_Manutencao]],'Tratamento de Dados 2025'!G$11,Tabela1[[Mês Fechamento]:[Mês Fechamento]],'Tratamento de Dados 2025'!$C15,Tabela1[[Ano]:[Ano]],'Tratamento de Dados 2025'!$B15) -> 0 | H15: =SUMIFS(Tabela1[[Custo_Total]:[Custo_Total]],Tabela1[[Tipo_Manutencao]:[Tipo_Manutencao]],'Tratamento de Dados 2025'!H$11,Tabela1[[Mês Fechamento]:[Mês Fechamento]],'Tratamento de Dados 2025'!$C15,Tabela1[[Ano]:[Ano]],'Tratamento de Dados 2025'!$B15) -> 0 | I15: =Tabela4[[#This Row],[Faturemento Mensal]]*$G$1 -> 3806.6328 | J15: =SUM(Tabela4[[#This Row],[Corretiva não programada]:[Melhoria de Máquinas]]) -> 3401.72
A16: 1605719 | B16: 2025 | C16: Maio | D16: =SUMIFS(Tabela1[[Custo_Total]:[Custo_Total]],Tabela1[[Tipo_Manutencao]:[Tipo_Manutencao]],'Tratamento de Dados 2025'!D$11,Tabela1[[Mês Fechamento]:[Mês Fechamento]],'Tratamento de Dados 2025'!$C16,Tabela1[[Ano]:[Ano]],'Tratamento de Dados 2025'!$B16) -> 2820.65 | E16: =SUMIFS(Tabela1[[Custo_Total]:[Custo_Total]],Tabela1[[Tipo_Manutencao]:[Tipo_Manutencao]],'Tratamento de Dados 2025'!E$11,Tabela1[[Mês Fechamento]:[Mês Fechamento]],'Tratamento de Dados 2025'!$C16,Tabela1[[Ano]:[Ano]],'Tratamento de Dados 2025'!$B16) -> 555 | F16: =SUMIFS(Tabela1[[Custo_Total]:[Custo_Total]],Tabela1[[Tipo_Manutencao]:[Tipo_Manutencao]],'Tratamento de Dados 2025'!F$11,Tabela1[[Mês Fechamento]:[Mês Fechamento]],'Tratamento de Dados 2025'!$C16,Tabela1[[Ano]:[Ano]],'Tratamento de Dados 2025'!$B16) -> 3687 | G16: =SUMIFS(Tabela1[[Custo_Total]:[Custo_Total]],Tabela1[[Tipo_Manutencao]:[Tipo_Manutencao]],'Tratamento de Dados 2025'!G$11,Tabela1[[Mês Fechamento]:[Mês Fechamento]],'Tratamento de Dados 2025'!$C16,Tabela1[[Ano]:[Ano]],'Tratamento de Dados 2025'!$B16) -> 0 | H16: =SUMIFS(Tabela1[[Custo_Total]:[Custo_Total]],Tabela1[[Tipo_Manutencao]:[Tipo_Manutencao]],'Tratamento de Dados 2025'!H$11,Tabela1[[Mês Fechamento]:[Mês Fechamento]],'Tratamento de Dados 2025'!$C16,Tabela1[[Ano]:[Ano]],'Tratamento de Dados 2025'!$B16) -> 0 | I16: =Tabela4[[#This Row],[Faturemento Mensal]]*$G$1 -> 8028.5949 | J16: =SUM(Tabela4[[#This Row],[Corretiva não programada]:[Melhoria de Máquinas]]) -> 7062.65
A17: 1219442.8 | B17: 2025 | C17: Junho | D17: =SUMIFS(Tabela1[[Custo_Total]:[Custo_Total]],Tabela1[[Tipo_Manutencao]:[Tipo_Manutencao]],'Tratamento de Dados 2025'!D$11,Tabela1[[Mês Fechamento]:[Mês Fechamento]],'Tratamento de Dados 2025'!$C17,Tabela1[[Ano]:[Ano]],'Tratamento de Dados 2025'!$B17) -> 503.03 | E17: =SUMIFS(Tabela1[[Custo_Total]:[Custo_Total]],Tabela1[[Tipo_Manutencao]:[Tipo_Manutencao]],'Tratamento de Dados 2025'!E$11,Tabela1[[Mês Fechamento]:[Mês Fechamento]],'Tratamento de Dados 2025'!$C17,Tabela1[[Ano]:[Ano]],'Tratamento de Dados 2025'!$B17) -> 0 | F17: =SUMIFS(Tabela1[[Custo_Total]:[Custo_Total]],Tabela1[[Tipo_Manutencao]:[Tipo_Manutencao]],'Tratamento de Dados 2025'!F$11,Tabela1[[Mês Fechamento]:[Mês Fechamento]],'Tratamento de Dados 2025'!$C17,Tabela1[[Ano]:[Ano]],'Tratamento de Dados 2025'!$B17) -> 4200 | G17: =SUMIFS(Tabela1[[Custo_Total]:[Custo_Total]],Tabela1[[Tipo_Manutencao]:[Tipo_Manutencao]],'Tratamento de Dados 2025'!G$11,Tabela1[[Mês Fechamento]:[Mês Fechamento]],'Tratamento de Dados 2025'!$C17,Tabela1[[Ano]:[Ano]],'Tratamento de Dados 2025'!$B17) -> 0 | H17: =SUMIFS(Tabela1[[Custo_Total]:[Custo_Total]],Tabela1[[Tipo_Manutencao]:[Tipo_Manutencao]],'Tratamento de Dados 2025'!H$11,Tabela1[[Mês Fechamento]:[Mês Fechamento]],'Tratamento de Dados 2025'!$C17,Tabela1[[Ano]:[Ano]],'Tratamento de Dados 2025'!$B17) -> 0 | I17: =Tabela4[[#This Row],[Faturemento Mensal]]*$G$1 -> 6097.214 | J17: =SUM(Tabela4[[#This Row],[Corretiva não programada]:[Melhoria de Máquinas]]) -> 4703.03
A18: 886919.59 | B18: 2025 | C18: Julho | D18: =SUMIFS(Tabela1[[Custo_Total]:[Custo_Total]],Tabela1[[Tipo_Manutencao]:[Tipo_Manutencao]],'Tratamento de Dados 2025'!D$11,Tabela1[[Mês Fechamento]:[Mês Fechamento]],'Tratamento de Dados 2025'!$C18,Tabela1[[Ano]:[Ano]],'Tratamento de Dados 2025'!$B18) -> 0 | E18: =SUMIFS(Tabela1[[Custo_Total]:[Custo_Total]],Tabela1[[Tipo_Manutencao]:[Tipo_Manutencao]],'Tratamento de Dados 2025'!E$11,Tabela1[[Mês Fechamento]:[Mês Fechamento]],'Tratamento de Dados 2025'!$C18,Tabela1[[Ano]:[Ano]],'Tratamento de Dados 2025'!$B18) -> 0 | F18: =SUMIFS(Tabela1[[Custo_Total]:[Custo_Total]],Tabela1[[Tipo_Manutencao]:[Tipo_Manutencao]],'Tratamento de Dados 2025'!F$11,Tabela1[[Mês Fechamento]:[Mês Fechamento]],'Tratamento de Dados 2025'!$C18,Tabela1[[Ano]:[Ano]],'Tratamento de Dados 2025'!$B18) -> 4200 | G18: =SUMIFS(Tabela1[[Custo_Total]:[Custo_Total]],Tabela1[[Tipo_Manutencao]:[Tipo_Manutencao]],'Tratamento de Dados 2025'!G$11,Tabela1[[Mês Fechamento]:[Mês Fechamento]],'Tratamento de Dados 2025'!$C18,Tabela1[[Ano]:[Ano]],'Tratamento de Dados 2025'!$B18) -> 0 | H18: =SUMIFS(Tabela1[[Custo_Total]:[Custo_Total]],Tabela1[[Tipo_Manutencao]:[Tipo_Manutencao]],'Tratamento de Dados 2025'!H$11,Tabela1[[Mês Fechamento]:[Mês Fechamento]],'Tratamento de Dados 2025'!$C18,Tabela1[[Ano]:[Ano]],'Tratamento de Dados 2025'!$B18) -> 0 | I18: =Tabela4[[#This Row],[Faturemento Mensal]]*$G$1 -> 4434.598 | J18: =SUM(Tabela4[[#This Row],[Corretiva não programada]:[Melhoria de Máquinas]]) -> 4200
A19: 836445.74 | B19: 2025 | C19: Agosto | D19: =SUMIFS(Tabela1[[Custo_Total]:[Custo_Total]],Tabela1[[Tipo_Manutencao]:[Tipo_Manutencao]],'Tratamento de Dados 2025'!D$11,Tabela1[[Mês Fechamento]:[Mês Fechamento]],'Tratamento de Dados 2025'!$C19,Tabela1[[Ano]:[Ano]],'Tratamento de Dados 2025'!$B19) -> 0 | E19: =SUMIFS(Tabela1[[Custo_Total]:[Custo_Total]],Tabela1[[Tipo_Manutencao]:[Tipo_Manutencao]],'Tratamento de Dados 2025'!E$11,Tabela1[[Mês Fechamento]:[Mês Fechamento]],'Tratamento de Dados 2025'!$C19,Tabela1[[Ano]:[Ano]],'Tratamento de Dados 2025'!$B19) -> 2372.14 | F19: =SUMIFS(Tabela1[[Custo_Total]:[Custo_Total]],Tabela1[[Tipo_Manutencao]:[Tipo_Manutencao]],'Tratamento de Dados 2025'!F$11,Tabela1[[Mês Fechamento]:[Mês Fechamento]],'Tratamento de Dados 2025'!$C19,Tabela1[[Ano]:[Ano]],'Tratamento de Dados 2025'!$B19) -> 2100 | G19: =SUMIFS(Tabela1[[Custo_Total]:[Custo_Total]],Tabela1[[Tipo_Manutencao]:[Tipo_Manutencao]],'Tratamento de Dados 2025'!G$11,Tabela1[[Mês Fechamento]:[Mês Fechamento]],'Tratamento de Dados 2025'!$C19,Tabela1[[Ano]:[Ano]],'Tratamento de Dados 2025'!$B19) -> 0 | H19: =SUMIFS(Tabela1[[Custo_Total]:[Custo_Total]],Tabela1[[Tipo_Manutencao]:[Tipo_Manutencao]],'Tratamento de Dados 2025'!H$11,Tabela1[[Mês Fechamento]:[Mês Fechamento]],'Tratamento de Dados 2025'!$C19,Tabela1[[Ano]:[Ano]],'Tratamento de Dados 2025'!$B19) -> 0 | I19: =Tabela4[[#This Row],[Faturemento Mensal]]*$G$1 -> 4182.2287 | J19: =SUM(Tabela4[[#This Row],[Corretiva não programada]:[Melhoria de Máquinas]]) -> 4472.14
A20: 635862.29 | B20: 2025 | C20: Setembro | D20: =SUMIFS(Tabela1[[Custo_Total]:[Custo_Total]],Tabela1[[Tipo_Manutencao]:[Tipo_Manutencao]],'Tratamento de Dados 2025'!D$11,Tabela1[[Mês Fechamento]:[Mês Fechamento]],'Tratamento de Dados 2025'!$C20,Tabela1[[Ano]:[Ano]],'Tratamento de Dados 2025'!$B20) -> 300 | E20: =SUMIFS(Tabela1[[Custo_Total]:[Custo_Total]],Tabela1[[Tipo_Manutencao]:[Tipo_Manutencao]],'Tratamento de Dados 2025'!E$11,Tabela1[[Mês Fechamento]:[Mês Fechamento]],'Tratamento de Dados 2025'!$C20,Tabela1[[Ano]:[Ano]],'Tratamento de Dados 2025'!$B20) -> 976.67 | F20: =SUMIFS(Tabela1[[Custo_Total]:[Custo_Total]],Tabela1[[Tipo_Manutencao]:[Tipo_Manutencao]],'Tratamento de Dados 2025'!F$11,Tabela1[[Mês Fechamento]:[Mês Fechamento]],'Tratamento de Dados 2025'!$C20,Tabela1[[Ano]:[Ano]],'Tratamento de Dados 2025'!$B20) -> 1200 | G20: =SUMIFS(Tabela1[[Custo_Total]:[Custo_Total]],Tabela1[[Tipo_Manutencao]:[Tipo_Manutencao]],'Tratamento de Dados 2025'!G$11,Tabela1[[Mês Fechamento]:[Mês Fechamento]],'Tratamento de Dados 2025'!$C20,Tabela1[[Ano]:[Ano]],'Tratamento de Dados 2025'!$B20) -> 0 | H20: =SUMIFS(Tabela1[[Custo_Total]:[Custo_Total]],Tabela1[[Tipo_Manutencao]:[Tipo_Manutencao]],'Tratamento de Dados 2025'!H$11,Tabela1[[Mês Fechamento]:[Mês Fechamento]],'Tratamento de Dados 2025'!$C20,Tabela1[[Ano]:[Ano]],'Tratamento de Dados 2025'!$B20) -> 0 | I20: =Tabela4[[#This Row],[Faturemento Mensal]]*$G$1 -> 3179.3115 | J20: =SUM(Tabela4[[#This Row],[Corretiva não programada]:[Melhoria de Máquinas]]) -> 2476.67
A21: 753559.98 | B21: 2025 | C21: Outubro | D21: =SUMIFS(Tabela1[[Custo_Total]:[Custo_Total]],Tabela1[[Tipo_Manutencao]:[Tipo_Manutencao]],'Tratamento de Dados 2025'!D$11,Tabela1[[Mês Fechamento]:[Mês Fechamento]],'Tratamento de Dados 2025'!$C21,Tabela1[[Ano]:[Ano]],'Tratamento de Dados 2025'!$B21) -> 0 | E21: =SUMIFS(Tabela1[[Custo_Total]:[Custo_Total]],Tabela1[[Tipo_Manutencao]:[Tipo_Manutencao]],'Tratamento de Dados 2025'!E$11,Tabela1[[Mês Fechamento]:[Mês Fechamento]],'Tratamento de Dados 2025'!$C21,Tabela1[[Ano]:[Ano]],'Tratamento de Dados 2025'!$B21) -> 2372.13 | F21: =SUMIFS(Tabela1[[Custo_Total]:[Custo_Total]],Tabela1[[Tipo_Manutencao]:[Tipo_Manutencao]],'Tratamento de Dados 2025'!F$11,Tabela1[[Mês Fechamento]:[Mês Fechamento]],'Tratamento de Dados 2025'!$C21,Tabela1[[Ano]:[Ano]],'Tratamento de Dados 2025'!$B21) -> 950 | G21: =SUMIFS(Tabela1[[Custo_Total]:[Custo_Total]],Tabela1[[Tipo_Manutencao]:[Tipo_Manutencao]],'Tratamento de Dados 2025'!G$11,Tabela1[[Mês Fechamento]:[Mês Fechamento]],'Tratamento de Dados 2025'!$C21,Tabela1[[Ano]:[Ano]],'Tratamento de Dados 2025'!$B21) -> 0 | H21: =SUMIFS(Tabela1[[Custo_Total]:[Custo_Total]],Tabela1[[Tipo_Manutencao]:[Tipo_Manutencao]],'Tratamento de Dados 2025'!H$11,Tabela1[[Mês Fechamento]:[Mês Fechamento]],'Tratamento de Dados 2025'!$C21,Tabela1[[Ano]:[Ano]],'Tratamento de Dados 2025'!$B21) -> 0 | I21: =Tabela4[[#This Row],[Faturemento Mensal]]*$G$1 -> 3767.7999 | J21: =SUM(Tabela4[[#This Row],[Corretiva não programada]:[Melhoria de Máquinas]]) -> 3322.13
A22: 518347.47 | B22: 2025 | C22: Novembro | D22: =SUMIFS(Tabela1[[Custo_Total]:[Custo_Total]],Tabela1[[Tipo_Manutencao]:[Tipo_Manutencao]],'Tratamento de Dados 2025'!D$11,Tabela1[[Mês Fechamento]:[Mês Fechamento]],'Tratamento de Dados 2025'!$C22,Tabela1[[Ano]:[Ano]],'Tratamento de Dados 2025'!$B22) -> 500 | E22: =SUMIFS(Tabela1[[Custo_Total]:[Custo_Total]],Tabela1[[Tipo_Manutencao]:[Tipo_Manutencao]],'Tratamento de Dados 2025'!E$11,Tabela1[[Mês Fechamento]:[Mês Fechamento]],'Tratamento de Dados 2025'!$C22,Tabela1[[Ano]:[Ano]],'Tratamento de Dados 2025'!$B22) -> 1775 | F22: =SUMIFS(Tabela1[[Custo_Total]:[Custo_Total]],Tabela1[[Tipo_Manutencao]:[Tipo_Manutencao]],'Tratamento de Dados 2025'!F$11,Tabela1[[Mês Fechamento]:[Mês Fechamento]],'Tratamento de Dados 2025'!$C22,Tabela1[[Ano]:[Ano]],'Tratamento de Dados 2025'!$B22) -> 0 | G22: =SUMIFS(Tabela1[[Custo_Total]:[Custo_Total]],Tabela1[[Tipo_Manutencao]:[Tipo_Manutencao]],'Tratamento de Dados 2025'!G$11,Tabela1[[Mês Fechamento]:[Mês Fechamento]],'Tratamento de Dados 2025'!$C22,Tabela1[[Ano]:[Ano]],'Tratamento de Dados 2025'!$B22) -> 0 | H22: =SUMIFS(Tabela1[[Custo_Total]:[Custo_Total]],Tabela1[[Tipo_Manutencao]:[Tipo_Manutencao]],'Tratamento de Dados 2025'!H$11,Tabela1[[Mês Fechamento]:[Mês Fechamento]],'Tratamento de Dados 2025'!$C22,Tabela1[[Ano]:[Ano]],'Tratamento de Dados 2025'!$B22) -> 0 | I22: =Tabela4[[#This Row],[Faturemento Mensal]]*$G$1 -> 2591.7373 | J22: =SUM(Tabela4[[#This Row],[Corretiva não programada]:[Melhoria de Máquinas]]) -> 2275
A23: 776659.91 | B23: 2025 | C23: Dezembro | D23: =SUMIFS(Tabela1[[Custo_Total]:[Custo_Total]],Tabela1[[Tipo_Manutencao]:[Tipo_Manutencao]],'Tratamento de Dados 2025'!D$11,Tabela1[[Mês Fechamento]:[Mês Fechamento]],'Tratamento de Dados 2025'!$C23,Tabela1[[Ano]:[Ano]],'Tratamento de Dados 2025'!$B23) -> 1817.62 | E23: =SUMIFS(Tabela1[[Custo_Total]:[Custo_Total]],Tabela1[[Tipo_Manutencao]:[Tipo_Manutencao]],'Tratamento de Dados 2025'!E$11,Tabela1[[Mês Fechamento]:[Mês Fechamento]],'Tratamento de Dados 2025'!$C23,Tabela1[[Ano]:[Ano]],'Tratamento de Dados 2025'!$B23) -> 1758.2 | F23: =SUMIFS(Tabela1[[Custo_Total]:[Custo_Total]],Tabela1[[Tipo_Manutencao]:[Tipo_Manutencao]],'Tratamento de Dados 2025'!F$11,Tabela1[[Mês Fechamento]:[Mês Fechamento]],'Tratamento de Dados 2025'!$C23,Tabela1[[Ano]:[Ano]],'Tratamento de Dados 2025'!$B23) -> 0 | G23: =SUMIFS(Tabela1[[Custo_Total]:[Custo_Total]],Tabela1[[Tipo_Manutencao]:[Tipo_Manutencao]],'Tratamento de Dados 2025'!G$11,Tabela1[[Mês Fechamento]:[Mês Fechamento]],'Tratamento de Dados 2025'!$C23,Tabela1[[Ano]:[Ano]],'Tratamento de Dados 2025'!$B23) -> 0 | H23: =SUMIFS(Tabela1[[Custo_Total]:[Custo_Total]],Tabela1[[Tipo_Manutencao]:[Tipo_Manutencao]],'Tratamento de Dados 2025'!H$11,Tabela1[[Mês Fechamento]:[Mês Fechamento]],'Tratamento de Dados 2025'!$C23,Tabela1[[Ano]:[Ano]],'Tratamento de Dados 2025'!$B23) -> 0 | I23: =Tabela4[[#This Row],[Faturemento Mensal]]*$G$1 -> 3883.2996 | J23: =SUM(Tabela4[[#This Row],[Corretiva não programada]:[Melhoria de Máquinas]]) -> 3575.82

Sheet Planilha2
A3: Rótulos de Linha | B3: Corretiva não programada Total | C3: Corretiva programada Total | D3: Manutenção Preventiva Total | E3: Manutenção Preditiva Total | F3: Soma de Limite de custos
A4: 2025 | B4: 40012.11 | C4: 21650.48 | D4: 43775 | E4: 0 | F4: 60000
A5: Janeiro | B5: 5992.48 | C5: 2976.1 | D5: 4200 | E5: 0 | F5: 5000
A6: Fevereiro | B6: 6150.51 | C6: 2288.54 | D6: 4200 | E6: 0 | F6: 5000
A7: Março | B7: 3431.61 | C7: 1863.39 | D7: 4200 | E7: 0 | F7: 5000
A8: Abril | B8: 5788.41 | C8: 690.45 | D8: 4200 | E8: 0 | F8: 5000
A9: Maio | B9: 7191.11 | C9: 0 | D9: 4200 | E9: 0 | F9: 5000
A10: Junho | B10: 503.03 | C10: 0 | D10: 4200 | E10: 0 | F10: 5000
A11: Julho | B11: 0 | C11: 0 | D11: 4200 | E11: 0 | F11: 5000
A12: Agosto | B12: 0 | C12: 2372.14 | D12: 4200 | E12: 0 | F12: 5000
A13: Setembro | B13: 1276.67 | C13: 2372.13 | D13: 4200 | E13: 0 | F13: 5000
A14: Outubro | B14: 976.67 | C14: 2372.13 | D14: 4200 | E14: 0 | F14: 5000
A15: Novembro | B15: 500 | C15: 4007.4 | D15: 1775 | E15: 0 | F15: 5000
A16: Dezembro | B16: 8201.62 | C16: 2708.2 | D16: 0 | E16: 0 | F16: 5000
A17: 2026 | B17: 8358.2 | C17: 7683 | D17: 0 | E17: 0 | F17: 10000
A18: Janeiro | B18: 6558.2 | C18: 2758 | D18: 0 | E18: 0 | F18: 5000
A19: Fevereiro | B19: 1800 | C19: 4925 | D19: 0 | E19: 0 | F19: 5000
A20: Total Geral | B20: 48370.31 | C20: 29333.48 | D20: 43775 | E20: 0 | F20: 70000

Sheet Graficos de Custos 2025

Sheet Tratamento de Dados 2026
B1: Resumo de Custos por Tipo de Manutenção | D1: 2026 | F1: Meta | G1: 0.005
B2: Tipo de manutenção | C2: Custo Total por tipo de manutenção (R$) | D2: Percentual de custo total por tipo
B3: Corretiva não programada | C3: =SUMIFS(Dados_OS!L:L,Dados_OS!H:H,Tabela54[[#This Row],[Tipo de manutenção]],Dados_OS!D:D,'Tratamento de Dados 2026'!$D$1) -> 21982.22 | D3: =Tabela54[[#This Row],[Custo Total por tipo de manutenção (R$)]]/SUM(Tabela54[Custo Total por tipo de manutenção (R$)]) -> 0.71275224
B4: Corretiva programada | C4: =SUMIFS(Dados_OS!L:L,Dados_OS!H:H,Tabela54[[#This Row],[Tipo de manutenção]],Dados_OS!D:D,'Tratamento de Dados 2026'!$D$1) -> 7563.33 | D4: =Tabela54[[#This Row],[Custo Total por tipo de manutenção (R$)]]/SUM(Tabela54[Custo Total por tipo de manutenção (R$)]) -> 0.24523367
B5: Preventiva | C5: =SUMIFS(Dados_OS!L:L,Dados_OS!H:H,Tabela54[[#This Row],[Tipo de manutenção]],Dados_OS!D:D,'Tratamento de Dados 2026'!$D$1) -> 0 | D5: =Tabela54[[#This Row],[Custo Total por tipo de manutenção (R$)]]/SUM(Tabela54[Custo Total por tipo de manutenção (R$)]) -> 0
B6: Preditiva | C6: =SUMIFS(Dados_OS!L:L,Dados_OS!H:H,Tabela54[[#This Row],[Tipo de manutenção]],Dados_OS!D:D,'Tratamento de Dados 2026'!$D$1) -> 0 | D6: =Tabela54[[#This Row],[Custo Total por tipo de manutenção (R$)]]/SUM(Tabela54[Custo Total por tipo de manutenção (R$)]) -> 0
B7: Melhoria | C7: =SUMIFS(Dados_OS!L:L,Dados_OS!H:H,Tabela54[[#This Row],[Tipo de manutenção]],Dados_OS!D:D,'Tratamento de Dados 2026'!$D$1) -> 1295.77 | D7: =Tabela54[[#This Row],[Custo Total por tipo de manutenção (R$)]]/SUM(Tabela54[Custo Total por tipo de manutenção (R$)]) -> 0.04201409
D8: =SUM(D3:D7) -> 1
A10: Custo de manutenção mensal
A11: Faturamento Mensal | B11: Ano | C11: Mês | D11: Corretiva não programada | E11: Corretiva programada | F11: Preventiva | G11: Preditiva | H11: Melhoria | I11: 0,5% do Faturamento Bruto Mensal | J11: Total Geral
A12: 647585.7 | B12: 2026 | C12: Janeiro | D12: =SUMIFS(Tabela1[[Custo_Total]:[Custo_Total]],Tabela1[[Tipo_Manutencao]:[Tipo_Manutencao]],'Tratamento de Dados 2026'!D$11,Tabela1[[Mês Fechamento]:[Mês Fechamento]],'Tratamento de Dados 2026'!$C12,Tabela1[[Ano]:[Ano]],'Tratamento de Dados 2026'!$B12) -> 2330 | E12: =SUMIFS(Tabela1[[Custo_Total]:[Custo_Total]],Tabela1[[Tipo_Manutencao]:[Tipo_Manutencao]],'Tratamento de Dados 2026'!E$11,Tabela1[[Mês Fechamento]:[Mês Fechamento]],'Tratamento de Dados 2026'!$C12,Tabela1[[Ano]:[Ano]],'Tratamento de Dados 2026'!$B12) -> 900 | F12: =SUMIFS(Tabela1[[Custo_Total]:[Custo_Total]],Tabela1[[Tipo_Manutencao]:[Tipo_Manutencao]],'Tratamento de Dados 2026'!F$11,Tabela1[[Mês Fechamento]:[Mês Fechamento]],'Tratamento de Dados 2026'!$C12,Tabela1[[Ano]:[Ano]],'Tratamento de Dados 2026'!$B12) -> 0 | G12: =SUMIFS(Tabela1[[Custo_Total]:[Custo_Total]],Tabela1[[Tipo_Manutencao]:[Tipo_Manutencao]],'Tratamento de Dados 2026'!G$11,Tabela1[[Mês Fechamento]:[Mês Fechamento]],'Tratamento de Dados 2026'!$C12,Tabela1[[Ano]:[Ano]],'Tratamento de Dados 2026'!$B12) -> 0 | H12: =SUMIFS(Tabela1[[Custo_Total]:[Custo_Total]],Tabela1[[Tipo_Manutencao]:[Tipo_Manutencao]],'Tratamento de Dados 2026'!H$11,Tabela1[[Mês Fechamento]:[Mês Fechamento]],'Tratamento de Dados 2026'!$C12,Tabela1[[Ano]:[Ano]],'Tratamento de Dados 2026'!$B12) -> 0 | I12: =A12*$G$1 -> 3237.9285 | J12: =SUM(Tabela43[[#This Row],[Corretiva não programada]:[Melhoria]]) -> 3230
A13: 844687.4 | B13: 2026 | C13: Fevereiro | D13: =SUMIFS(Tabela1[[Custo_Total]:[Custo_Total]],Tabela1[[Tipo_Manutencao]:[Tipo_Manutencao]],'Tratamento de Dados 2026'!D$11,Tabela1[[Mês Fechamento]:[Mês Fechamento]],'Tratamento de Dados 2026'!$C13,Tabela1[[Ano]:[Ano]],'Tratamento de Dados 2026'!$B13) -> 1800 | E13: =SUMIFS(Tabela1[[Custo_Total]:[Custo_Total]],Tabela1[[Tipo_Manutencao]:[Tipo_Manutencao]],'Tratamento de Dados 2026'!E$11,Tabela1[[Mês Fechamento]:[Mês Fechamento]],'Tratamento de Dados 2026'!$C13,Tabela1[[Ano]:[Ano]],'Tratamento de Dados 2026'!$B13) -> 2445 | F13: =SUMIFS(Tabela1[[Custo_Total]:[Custo_Total]],Tabela1[[Tipo_Manutencao]:[Tipo_Manutencao]],'Tratamento de Dados 2026'!F$11,Tabela1[[Mês Fechamento]:[Mês Fechamento]],'Tratamento de Dados 2026'!$C13,Tabela1[[Ano]:[Ano]],'Tratamento de Dados 2026'!$B13) -> 0 | G13: =SUMIFS(Tabela1[[Custo_Total]:[Custo_Total]],Tabela1[[Tipo_Manutencao]:[Tipo_Manutencao]],'Tratamento de Dados 2026'!G$11,Tabela1[[Mês Fechamento]:[Mês Fechamento]],'Tratamento de Dados 2026'!$C13,Tabela1[[Ano]:[Ano]],'Tratamento de Dados 2026'!$B13) -> 0 | H13: =SUMIFS(Tabela1[[Custo_Total]:[Custo_Total]],Tabela1[[Tipo_Manutencao]:[Tipo_Manutencao]],'Tratamento de Dados 2026'!H$11,Tabela1[[Mês Fechamento]:[Mês Fechamento]],'Tratamento de Dados 2026'!$C13,Tabela1[[Ano]:[Ano]],'Tratamento de Dados 2026'!$B13) -> 600 | I13: =A13*$G$1 -> 4223.437 | J13: =SUM(Tabela43[[#This Row],[Corretiva não programada]:[Melhoria]]) -> 4845
A14: 753982.97 | B14: 2026 | C14: Março | D14: =SUMIFS(Tabela1[[Custo_Total]:[Custo_Total]],Tabela1[[Tipo_Manutencao]:[Tipo_Manutencao]],'Tratamento de Dados 2026'!D$11,Tabela1[[Mês Fechamento]:[Mês Fechamento]],'Tratamento de Dados 2026'!$C14,Tabela1[[Ano]:[Ano]],'Tratamento de Dados 2026'!$B14) -> 10476.22 | E14: =SUMIFS(Tabela1[[Custo_Total]:[Custo_Total]],Tabela1[[Tipo_Manutencao]:[Tipo_Manutencao]],'Tratamento de Dados 2026'!E$11,Tabela1[[Mês Fechamento]:[Mês Fechamento]],'Tratamento de Dados 2026'!$C14,Tabela1[[Ano]:[Ano]],'Tratamento de Dados 2026'!$B14) -> 460 | F14: =SUMIFS(Tabela1[[Custo_Total]:[Custo_Total]],Tabela1[[Tipo_Manutencao]:[Tipo_Manutencao]],'Tratamento de Dados 2026'!F$11,Tabela1[[Mês Fechamento]:[Mês Fechamento]],'Tratamento de Dados 2026'!$C14,Tabela1[[Ano]:[Ano]],'Tratamento de Dados 2026'!$B14) -> 0 | G14: =SUMIFS(Tabela1[[Custo_Total]:[Custo_Total]],Tabela1[[Tipo_Manutencao]:[Tipo_Manutencao]],'Tratamento de Dados 2026'!G$11,Tabela1[[Mês Fechamento]:[Mês Fechamento]],'Tratamento de Dados 2026'!$C14,Tabela1[[Ano]:[Ano]],'Tratamento de Dados 2026'!$B14) -> 0 | H14: =SUMIFS(Tabela1[[Custo_Total]:[Custo_Total]],Tabela1[[Tipo_Manutencao]:[Tipo_Manutencao]],'Tratamento de Dados 2026'!H$11,Tabela1[[Mês Fechamento]:[Mês Fechamento]],'Tratamento de Dados 2026'!$C14,Tabela1[[Ano]:[Ano]],'Tratamento de Dados 2026'!$B14) -> 0 | I14: =A14*$G$1 -> 3769.9149 | J14: =SUM(Tabela43[[#This Row],[Corretiva não programada]:[Melhoria]]) -> 10936.22
A15: 907675.67 | B15: 2026 | C15: Abril | D15: =SUMIFS(Tabela1[[Custo_Total]:[Custo_Total]],Tabela1[[Tipo_Manutencao]:[Tipo_Manutencao]],'Tratamento de Dados 2026'!D$11,Tabela1[[Mês Fechamento]:[Mês Fechamento]],'Tratamento de Dados 2026'!$C15,Tabela1[[Ano]:[Ano]],'Tratamento de Dados 2026'!$B15) -> 0 | E15: =SUMIFS(Tabela1[[Custo_Total]:[Custo_Total]],Tabela1[[Tipo_Manutencao]:[Tipo_Manutencao]],'Tratamento de Dados 2026'!E$11,Tabela1[[Mês Fechamento]:[Mês Fechamento]],'Tratamento de Dados 2026'!$C15,Tabela1[[Ano]:[Ano]],'Tratamento de Dados 2026'!$B15) -> 3583.33 | F15: =SUMIFS(Tabela1[[Custo_Total]:[Custo_Total]],Tabela1[[Tipo_Manutencao]:[Tipo_Manutencao]],'Tratamento de Dados 2026'!F$11,Tabela1[[Mês Fechamento]:[Mês Fechamento]],'Tratamento de Dados 2026'!$C15,Tabela1[[Ano]:[Ano]],'Tratamento de Dados 2026'!$B15) -> 0 | G15: =SUMIFS(Tabela1[[Custo_Total]:[Custo_Total]],Tabela1[[Tipo_Manutencao]:[Tipo_Manutencao]],'Tratamento de Dados 2026'!G$11,Tabela1[[Mês Fechamento]:[Mês Fechamento]],'Tratamento de Dados 2026'!$C15,Tabela1[[Ano]:[Ano]],'Tratamento de Dados 2026'!$B15) -> 0 | H15: =SUMIFS(Tabela1[[Custo_Total]:[Custo_Total]],Tabela1[[Tipo_Manutencao]:[Tipo_Manutencao]],'Tratamento de Dados 2026'!H$11,Tabela1[[Mês Fechamento]:[Mês Fechamento]],'Tratamento de Dados 2026'!$C15,Tabela1[[Ano]:[Ano]],'Tratamento de Dados 2026'!$B15) -> 0 | I15: =A15*$G$1 -> 4538.3783 | J15: =SUM(Tabela43[[#This Row],[Corretiva não programada]:[Melhoria]]) -> 3583.33
A16: 884756.31 | B16: 2026 | C16: Maio | D16: =SUMIFS(Tabela1[[Custo_Total]:[Custo_Total]],Tabela1[[Tipo_Manutencao]:[Tipo_Manutencao]],'Tratamento de Dados 2026'!D$11,Tabela1[[Mês Fechamento]:[Mês Fechamento]],'Tratamento de Dados 2026'!$C16,Tabela1[[Ano]:[Ano]],'Tratamento de Dados 2026'!$B16) -> 7376 | E16: =SUMIFS(Tabela1[[Custo_Total]:[Custo_Total]],Tabela1[[Tipo_Manutencao]:[Tipo_Manutencao]],'Tratamento de Dados 2026'!E$11,Tabela1[[Mês Fechamento]:[Mês Fechamento]],'Tratamento de Dados 2026'!$C16,Tabela1[[Ano]:[Ano]],'Tratamento de Dados 2026'!$B16) -> 175 | F16: =SUMIFS(Tabela1[[Custo_Total]:[Custo_Total]],Tabela1[[Tipo_Manutencao]:[Tipo_Manutencao]],'Tratamento de Dados 2026'!F$11,Tabela1[[Mês Fechamento]:[Mês Fechamento]],'Tratamento de Dados 2026'!$C16,Tabela1[[Ano]:[Ano]],'Tratamento de Dados 2026'!$B16) -> 0 | G16: =SUMIFS(Tabela1[[Custo_Total]:[Custo_Total]],Tabela1[[Tipo_Manutencao]:[Tipo_Manutencao]],'Tratamento de Dados 2026'!G$11,Tabela1[[Mês Fechamento]:[Mês Fechamento]],'Tratamento de Dados 2026'!$C16,Tabela1[[Ano]:[Ano]],'Tratamento de Dados 2026'!$B16) -> 0 | H16: =SUMIFS(Tabela1[[Custo_Total]:[Custo_Total]],Tabela1[[Tipo_Manutencao]:[Tipo_Manutencao]],'Tratamento de Dados 2026'!H$11,Tabela1[[Mês Fechamento]:[Mês Fechamento]],'Tratamento de Dados 2026'!$C16,Tabela1[[Ano]:[Ano]],'Tratamento de Dados 2026'!$B16) -> 695.77 | I16: =A16*$G$1 -> 4423.7816 | J16: =SUM(Tabela43[[#This Row],[Corretiva não programada]:[Melhoria]]) -> 8246.77
A17: 0 | B17: 2026 | C17: Junho | D17: =SUMIFS(Tabela1[[Custo_Total]:[Custo_Total]],Tabela1[[Tipo_Manutencao]:[Tipo_Manutencao]],'Tratamento de Dados 2026'!D$11,Tabela1[[Mês Fechamento]:[Mês Fechamento]],'Tratamento de Dados 2026'!$C17,Tabela1[[Ano]:[Ano]],'Tratamento de Dados 2026'!$B17) -> 0 | E17: =SUMIFS(Tabela1[[Custo_Total]:[Custo_Total]],Tabela1[[Tipo_Manutencao]:[Tipo_Manutencao]],'Tratamento de Dados 2026'!E$11,Tabela1[[Mês Fechamento]:[Mês Fechamento]],'Tratamento de Dados 2026'!$C17,Tabela1[[Ano]:[Ano]],'Tratamento de Dados 2026'!$B17) -> 0 | F17: =SUMIFS(Tabela1[[Custo_Total]:[Custo_Total]],Tabela1[[Tipo_Manutencao]:[Tipo_Manutencao]],'Tratamento de Dados 2026'!F$11,Tabela1[[Mês Fechamento]:[Mês Fechamento]],'Tratamento de Dados 2026'!$C17,Tabela1[[Ano]:[Ano]],'Tratamento de Dados 2026'!$B17) -> 0 | G17: =SUMIFS(Tabela1[[Custo_Total]:[Custo_Total]],Tabela1[[Tipo_Manutencao]:[Tipo_Manutencao]],'Tratamento de Dados 2026'!G$11,Tabela1[[Mês Fechamento]:[Mês Fechamento]],'Tratamento de Dados 2026'!$C17,Tabela1[[Ano]:[Ano]],'Tratamento de Dados 2026'!$B17) -> 0 | H17: =SUMIFS(Tabela1[[Custo_Total]:[Custo_Total]],Tabela1[[Tipo_Manutencao]:[Tipo_Manutencao]],'Tratamento de Dados 2026'!H$11,Tabela1[[Mês Fechamento]:[Mês Fechamento]],'Tratamento de Dados 2026'!$C17,Tabela1[[Ano]:[Ano]],'Tratamento de Dados 2026'!$B17) -> 0 | I17: =A17*$G$1 -> 0 | J17: =SUM(Tabela43[[#This Row],[Corretiva não programada]:[Melhoria]]) -> 0
A18: 0 | B18: 2026 | C18: Julho | D18: =SUMIFS(Tabela1[[Custo_Total]:[Custo_Total]],Tabela1[[Tipo_Manutencao]:[Tipo_Manutencao]],'Tratamento de Dados 2026'!D$11,Tabela1[[Mês Fechamento]:[Mês Fechamento]],'Tratamento de Dados 2026'!$C18,Tabela1[[Ano]:[Ano]],'Tratamento de Dados 2026'!$B18) -> 0 | E18: =SUMIFS(Tabela1[[Custo_Total]:[Custo_Total]],Tabela1[[Tipo_Manutencao]:[Tipo_Manutencao]],'Tratamento de Dados 2026'!E$11,Tabela1[[Mês Fechamento]:[Mês Fechamento]],'Tratamento de Dados 2026'!$C18,Tabela1[[Ano]:[Ano]],'Tratamento de Dados 2026'!$B18) -> 0 | F18: =SUMIFS(Tabela1[[Custo_Total]:[Custo_Total]],Tabela1[[Tipo_Manutencao]:[Tipo_Manutencao]],'Tratamento de Dados 2026'!F$11,Tabela1[[Mês Fechamento]:[Mês Fechamento]],'Tratamento de Dados 2026'!$C18,Tabela1[[Ano]:[Ano]],'Tratamento de Dados 2026'!$B18) -> 0 | G18: =SUMIFS(Tabela1[[Custo_Total]:[Custo_Total]],Tabela1[[Tipo_Manutencao]:[Tipo_Manutencao]],'Tratamento de Dados 2026'!G$11,Tabela1[[Mês Fechamento]:[Mês Fechamento]],'Tratamento de Dados 2026'!$C18,Tabela1[[Ano]:[Ano]],'Tratamento de Dados 2026'!$B18) -> 0 | H18: =SUMIFS(Tabela1[[Custo_Total]:[Custo_Total]],Tabela1[[Tipo_Manutencao]:[Tipo_Manutencao]],'Tratamento de Dados 2026'!H$11,Tabela1[[Mês Fechamento]:[Mês Fechamento]],'Tratamento de Dados 2026'!$C18,Tabela1[[Ano]:[Ano]],'Tratamento de Dados 2026'!$B18) -> 0 | I18: =A18*$G$1 -> 0 | J18: =SUM(Tabela43[[#This Row],[Corretiva não programada]:[Melhoria]]) -> 0
A19: 0 | B19: 2026 | C19: Agosto | D19: =SUMIFS(Tabela1[[Custo_Total]:[Custo_Total]],Tabela1[[Tipo_Manutencao]:[Tipo_Manutencao]],'Tratamento de Dados 2026'!D$11,Tabela1[[Mês Fechamento]:[Mês Fechamento]],'Tratamento de Dados 2026'!$C19,Tabela1[[Ano]:[Ano]],'Tratamento de Dados 2026'!$B19) -> 0 | E19: =SUMIFS(Tabela1[[Custo_Total]:[Custo_Total]],Tabela1[[Tipo_Manutencao]:[Tipo_Manutencao]],'Tratamento de Dados 2026'!E$11,Tabela1[[Mês Fechamento]:[Mês Fechamento]],'Tratamento de Dados 2026'!$C19,Tabela1[[Ano]:[Ano]],'Tratamento de Dados 2026'!$B19) -> 0 | F19: =SUMIFS(Tabela1[[Custo_Total]:[Custo_Total]],Tabela1[[Tipo_Manutencao]:[Tipo_Manutencao]],'Tratamento de Dados 2026'!F$11,Tabela1[[Mês Fechamento]:[Mês Fechamento]],'Tratamento de Dados 2026'!$C19,Tabela1[[Ano]:[Ano]],'Tratamento de Dados 2026'!$B19) -> 0 | G19: =SUMIFS(Tabela1[[Custo_Total]:[Custo_Total]],Tabela1[[Tipo_Manutencao]:[Tipo_Manutencao]],'Tratamento de Dados 2026'!G$11,Tabela1[[Mês Fechamento]:[Mês Fechamento]],'Tratamento de Dados 2026'!$C19,Tabela1[[Ano]:[Ano]],'Tratamento de Dados 2026'!$B19) -> 0 | H19: =SUMIFS(Tabela1[[Custo_Total]:[Custo_Total]],Tabela1[[Tipo_Manutencao]:[Tipo_Manutencao]],'Tratamento de Dados 2026'!H$11,Tabela1[[Mês Fechamento]:[Mês Fechamento]],'Tratamento de Dados 2026'!$C19,Tabela1[[Ano]:[Ano]],'Tratamento de Dados 2026'!$B19) -> 0 | I19: =A19*$G$1 -> 0 | J19: =SUM(Tabela43[[#This Row],[Corretiva não programada]:[Melhoria]]) -> 0
A20: 0 | B20: 2026 | C20: Setembro | D20: =SUMIFS(Tabela1[[Custo_Total]:[Custo_Total]],Tabela1[[Tipo_Manutencao]:[Tipo_Manutencao]],'Tratamento de Dados 2026'!D$11,Tabela1[[Mês Fechamento]:[Mês Fechamento]],'Tratamento de Dados 2026'!$C20,Tabela1[[Ano]:[Ano]],'Tratamento de Dados 2026'!$B20) -> 0 | E20: =SUMIFS(Tabela1[[Custo_Total]:[Custo_Total]],Tabela1[[Tipo_Manutencao]:[Tipo_Manutencao]],'Tratamento de Dados 2026'!E$11,Tabela1[[Mês Fechamento]:[Mês Fechamento]],'Tratamento de Dados 2026'!$C20,Tabela1[[Ano]:[Ano]],'Tratamento de Dados 2026'!$B20) -> 0 | F20: =SUMIFS(Tabela1[[Custo_Total]:[Custo_Total]],Tabela1[[Tipo_Manutencao]:[Tipo_Manutencao]],'Tratamento de Dados 2026'!F$11,Tabela1[[Mês Fechamento]:[Mês Fechamento]],'Tratamento de Dados 2026'!$C20,Tabela1[[Ano]:[Ano]],'Tratamento de Dados 2026'!$B20) -> 0 | G20: =SUMIFS(Tabela1[[Custo_Total]:[Custo_Total]],Tabela1[[Tipo_Manutencao]:[Tipo_Manutencao]],'Tratamento de Dados 2026'!G$11,Tabela1[[Mês Fechamento]:[Mês Fechamento]],'Tratamento de Dados 2026'!$C20,Tabela1[[Ano]:[Ano]],'Tratamento de Dados 2026'!$B20) -> 0 | H20: =SUMIFS(Tabela1[[Custo_Total]:[Custo_Total]],Tabela1[[Tipo_Manutencao]:[Tipo_Manutencao]],'Tratamento de Dados 2026'!H$11,Tabela1[[Mês Fechamento]:[Mês Fechamento]],'Tratamento de Dados 2026'!$C20,Tabela1[[Ano]:[Ano]],'Tratamento de Dados 2026'!$B20) -> 0 | I20: =A20*$G$1 -> 0 | J20: =SUM(Tabela43[[#This Row],[Corretiva não programada]:[Melhoria]]) -> 0
A21: 0 | B21: 2026 | C21: Outubro | D21: =SUMIFS(Tabela1[[Custo_Total]:[Custo_Total]],Tabela1[[Tipo_Manutencao]:[Tipo_Manutencao]],'Tratamento de Dados 2026'!D$11,Tabela1[[Mês Fechamento]:[Mês Fechamento]],'Tratamento de Dados 2026'!$C21,Tabela1[[Ano]:[Ano]],'Tratamento de Dados 2026'!$B21) -> 0 | E21: =SUMIFS(Tabela1[[Custo_Total]:[Custo_Total]],Tabela1[[Tipo_Manutencao]:[Tipo_Manutencao]],'Tratamento de Dados 2026'!E$11,Tabela1[[Mês Fechamento]:[Mês Fechamento]],'Tratamento de Dados 2026'!$C21,Tabela1[[Ano]:[Ano]],'Tratamento de Dados 2026'!$B21) -> 0 | F21: =SUMIFS(Tabela1[[Custo_Total]:[Custo_Total]],Tabela1[[Tipo_Manutencao]:[Tipo_Manutencao]],'Tratamento de Dados 2026'!F$11,Tabela1[[Mês Fechamento]:[Mês Fechamento]],'Tratamento de Dados 2026'!$C21,Tabela1[[Ano]:[Ano]],'Tratamento de Dados 2026'!$B21) -> 0 | G21: =SUMIFS(Tabela1[[Custo_Total]:[Custo_Total]],Tabela1[[Tipo_Manutencao]:[Tipo_Manutencao]],'Tratamento de Dados 2026'!G$11,Tabela1[[Mês Fechamento]:[Mês Fechamento]],'Tratamento de Dados 2026'!$C21,Tabela1[[Ano]:[Ano]],'Tratamento de Dados 2026'!$B21) -> 0 | H21: =SUMIFS(Tabela1[[Custo_Total]:[Custo_Total]],Tabela1[[Tipo_Manutencao]:[Tipo_Manutencao]],'Tratamento de Dados 2026'!H$11,Tabela1[[Mês Fechamento]:[Mês Fechamento]],'Tratamento de Dados 2026'!$C21,Tabela1[[Ano]:[Ano]],'Tratamento de Dados 2026'!$B21) -> 0 | I21: =A21*$G$1 -> 0 | J21: =SUM(Tabela43[[#This Row],[Corretiva não programada]:[Melhoria]]) -> 0
A22: 0 | B22: 2026 | C22: Novembro | D22: =SUMIFS(Tabela1[[Custo_Total]:[Custo_Total]],Tabela1[[Tipo_Manutencao]:[Tipo_Manutencao]],'Tratamento de Dados 2026'!D$11,Tabela1[[Mês Fechamento]:[Mês Fechamento]],'Tratamento de Dados 2026'!$C22,Tabela1[[Ano]:[Ano]],'Tratamento de Dados 2026'!$B22) -> 0 | E22: =SUMIFS(Tabela1[[Custo_Total]:[Custo_Total]],Tabela1[[Tipo_Manutencao]:[Tipo_Manutencao]],'Tratamento de Dados 2026'!E$11,Tabela1[[Mês Fechamento]:[Mês Fechamento]],'Tratamento de Dados 2026'!$C22,Tabela1[[Ano]:[Ano]],'Tratamento de Dados 2026'!$B22) -> 0 | F22: =SUMIFS(Tabela1[[Custo_Total]:[Custo_Total]],Tabela1[[Tipo_Manutencao]:[Tipo_Manutencao]],'Tratamento de Dados 2026'!F$11,Tabela1[[Mês Fechamento]:[Mês Fechamento]],'Tratamento de Dados 2026'!$C22,Tabela1[[Ano]:[Ano]],'Tratamento de Dados 2026'!$B22) -> 0 | G22: =SUMIFS(Tabela1[[Custo_Total]:[Custo_Total]],Tabela1[[Tipo_Manutencao]:[Tipo_Manutencao]],'Tratamento de Dados 2026'!G$11,Tabela1[[Mês Fechamento]:[Mês Fechamento]],'Tratamento de Dados 2026'!$C22,Tabela1[[Ano]:[Ano]],'Tratamento de Dados 2026'!$B22) -> 0 | H22: =SUMIFS(Tabela1[[Custo_Total]:[Custo_Total]],Tabela1[[Tipo_Manutencao]:[Tipo_Manutencao]],'Tratamento de Dados 2026'!H$11,Tabela1[[Mês Fechamento]:[Mês Fechamento]],'Tratamento de Dados 2026'!$C22,Tabela1[[Ano]:[Ano]],'Tratamento de Dados 2026'!$B22) -> 0 | I22: =A22*$G$1 -> 0 | J22: =SUM(Tabela43[[#This Row],[Corretiva não programada]:[Melhoria]]) -> 0
A23: 0 | B23: 2026 | C23: Dezembro | D23: =SUMIFS(Tabela1[[Custo_Total]:[Custo_Total]],Tabela1[[Tipo_Manutencao]:[Tipo_Manutencao]],'Tratamento de Dados 2026'!D$11,Tabela1[[Mês Fechamento]:[Mês Fechamento]],'Tratamento de Dados 2026'!$C23,Tabela1[[Ano]:[Ano]],'Tratamento de Dados 2026'!$B23) -> 0 | E23: =SUMIFS(Tabela1[[Custo_Total]:[Custo_Total]],Tabela1[[Tipo_Manutencao]:[Tipo_Manutencao]],'Tratamento de Dados 2026'!E$11,Tabela1[[Mês Fechamento]:[Mês Fechamento]],'Tratamento de Dados 2026'!$C23,Tabela1[[Ano]:[Ano]],'Tratamento de Dados 2026'!$B23) -> 0 | F23: =SUMIFS(Tabela1[[Custo_Total]:[Custo_Total]],Tabela1[[Tipo_Manutencao]:[Tipo_Manutencao]],'Tratamento de Dados 2026'!F$11,Tabela1[[Mês Fechamento]:[Mês Fechamento]],'Tratamento de Dados 2026'!$C23,Tabela1[[Ano]:[Ano]],'Tratamento de Dados 2026'!$B23) -> 0 | G23: =SUMIFS(Tabela1[[Custo_Total]:[Custo_Total]],Tabela1[[Tipo_Manutencao]:[Tipo_Manutencao]],'Tratamento de Dados 2026'!G$11,Tabela1[[Mês Fechamento]:[Mês Fechamento]],'Tratamento de Dados 2026'!$C23,Tabela1[[Ano]:[Ano]],'Tratamento de Dados 2026'!$B23) -> 0 | H23: =SUMIFS(Tabela1[[Custo_Total]:[Custo_Total]],Tabela1[[Tipo_Manutencao]:[Tipo_Manutencao]],'Tratamento de Dados 2026'!H$11,Tabela1[[Mês Fechamento]:[Mês Fechamento]],'Tratamento de Dados 2026'!$C23,Tabela1[[Ano]:[Ano]],'Tratamento de Dados 2026'!$B23) -> 0 | I23: =A23*$G$1 -> 0 | J23: =SUM(Tabela43[[#This Row],[Corretiva não programada]:[Melhoria]]) -> 0

Sheet Graficos de Custos 2026
